Thu Nov  5 21:00:28 CST 2020
Traceback (most recent call last):
  File "/mnt/c/Users/Image/Documents/GitHub/LSU_Herbarium_Imaging_Scripts/WorkflowScriptsWS2/MoveLocalImages.py", line 213, in moveFiles
    writeLog = open(logFilePath,'a')
FileNotFoundError: [Errno 2] No such file or directory: '/mnt/c/Users/Image/Desktop/Imaging/Logs/2020-11-05_local_ws2.txt'

During handling of the above exception, another exception occurred:

Traceback (most recent call last):
  File "/mnt/c/Users/Image/Documents/GitHub/LSU_Herbarium_Imaging_Scripts/WorkflowScriptsWS2/MoveLocalImages.py", line 337, in <module>
    main()
  File "/mnt/c/Users/Image/Documents/GitHub/LSU_Herbarium_Imaging_Scripts/WorkflowScriptsWS2/MoveLocalImages.py", line 322, in main
    moveFiles(sourceFolder,destinationFolder,portalFolders,otherFolders,barcodeMax,barcodeMin,outLogsuffix,errorFilePath,csvLogFilePath)
  File "/mnt/c/Users/Image/Documents/GitHub/LSU_Herbarium_Imaging_Scripts/WorkflowScriptsWS2/MoveLocalImages.py", line 219, in moveFiles
    writeError = open(errorFilePath,'a')
FileNotFoundError: [Errno 2] No such file or directory: '/mnt/c/Users/Image/Desktop/Imaging/Logs/2020-11-05-ERRORS.txt'
