Thu Nov  5 21:00:28 CST 2020
Traceback (most recent call last):
  File "/mnt/c/Users/Image/Documents/GitHub/LSU_Herbarium_Imaging_Scripts/WorkflowScriptsWS2/MoveLocalImages.py", line 213, in moveFiles
    writeLog = open(logFilePath,'a')
FileNotFoundError: [Errno 2] No such file or directory: '/mnt/c/Users/Image/Desktop/Imaging/Logs/2020-11-05_local_ws2.txt'

During handling of the above exception, another exception occurred:

Traceback (most recent call last):
  File "/mnt/c/Users/Image/Documents/GitHub/LSU_Herbarium_Imaging_Scripts/WorkflowScriptsWS2/MoveLocalImages.py", line 337, in <module>
    main()
  File "/mnt/c/Users/Image/Documents/GitHub/LSU_Herbarium_Imaging_Scripts/WorkflowScriptsWS2/MoveLocalImages.py", line 322, in main
    moveFiles(sourceFolder,destinationFolder,portalFolders,otherFolders,barcodeMax,barcodeMin,outLogsuffix,errorFilePath,csvLogFilePath)
  File "/mnt/c/Users/Image/Documents/GitHub/LSU_Herbarium_Imaging_Scripts/WorkflowScriptsWS2/MoveLocalImages.py", line 219, in moveFiles
    writeError = open(errorFilePath,'a')
FileNotFoundError: [Errno 2] No such file or directory: '/mnt/c/Users/Image/Desktop/Imaging/Logs/2020-11-05-ERRORS.txt'
Fri Nov  6 15:35:01 CST 2020
['2020-11-06', '22', '42', '22', '0', '0', '0', '0']
Done
Fri Nov  6 21:00:02 CST 2020
['2020-11-06', '0', '0', '0', '0', '0', '0', '0']
no images today
Done
Sat Nov  7 21:00:02 CST 2020
['2020-11-07', '0', '0', '0', '0', '0', '0', '0']
no images today
Done
Sun Nov  8 21:00:02 CST 2020
['2020-11-08', '0', '0', '0', '0', '0', '0', '0']
no images today
Done
Mon Nov  9 21:00:09 CST 2020
['2020-11-09', '0', '0', '0', '0', '0', '0', '0']
no images today
Done
Tue Nov 10 21:00:02 CST 2020
['2020-11-10', '0', '0', '0', '0', '0', '0', '0']
no images today
Done
